Traceback (most recent call last):
  File "/Library/Frameworks/Python.framework/Versions/3.8/lib/python3.8/site-packages/jupyter_cache/executors/utils.py", line 51, in single_nb_execution
    executenb(
  File "/Library/Frameworks/Python.framework/Versions/3.8/lib/python3.8/site-packages/nbclient/client.py", line 1087, in execute
    return NotebookClient(nb=nb, resources=resources, km=km, **kwargs).execute()
  File "/Library/Frameworks/Python.framework/Versions/3.8/lib/python3.8/site-packages/nbclient/util.py", line 74, in wrapped
    return just_run(coro(*args, **kwargs))
  File "/Library/Frameworks/Python.framework/Versions/3.8/lib/python3.8/site-packages/nbclient/util.py", line 53, in just_run
    return loop.run_until_complete(coro)
  File "/Library/Frameworks/Python.framework/Versions/3.8/lib/python3.8/asyncio/base_events.py", line 612, in run_until_complete
    return future.result()
  File "/Library/Frameworks/Python.framework/Versions/3.8/lib/python3.8/site-packages/nbclient/client.py", line 540, in async_execute
    await self.async_execute_cell(
  File "/Library/Frameworks/Python.framework/Versions/3.8/lib/python3.8/site-packages/nbclient/client.py", line 832, in async_execute_cell
    self._check_raise_for_error(cell, exec_reply)
  File "/Library/Frameworks/Python.framework/Versions/3.8/lib/python3.8/site-packages/nbclient/client.py", line 740, in _check_raise_for_error
    raise CellExecutionError.from_cell_and_msg(cell, exec_reply['content'])
nbclient.exceptions.CellExecutionError: An error occurred while executing the following cell:
------------------
import numpy as np
import pandas as pd
import matplotlib.pyplot as plt
import dask.bag as db
from dask.distributed import Client
import json
client = Client()
papers = db.read_text('arxiv-metadata-oai-snapshot-2020-08-14.json').map(json.loads)
------------------

[0;31m---------------------------------------------------------------------------[0m
[0;31mModuleNotFoundError[0m                       Traceback (most recent call last)
[0;32m/Library/Frameworks/Python.framework/Versions/3.8/lib/python3.8/site-packages/dask/bag/__init__.py[0m in [0;36m<module>[0;34m[0m
[1;32m      1[0m [0;32mtry[0m[0;34m:[0m[0;34m[0m[0;34m[0m[0m
[0;32m----> 2[0;31m     from .core import (
[0m[1;32m      3[0m         [0mBag[0m[0;34m,[0m[0;34m[0m[0;34m[0m[0m

[0;32m/Library/Frameworks/Python.framework/Versions/3.8/lib/python3.8/site-packages/dask/bag/core.py[0m in [0;36m<module>[0;34m[0m
[1;32m     12[0m [0;34m[0m[0m
[0;32m---> 13[0;31m [0;32mimport[0m [0mtlz[0m [0;32mas[0m [0mtoolz[0m[0;34m[0m[0;34m[0m[0m
[0m[1;32m     14[0m from tlz import (

[0;31mModuleNotFoundError[0m: No module named 'tlz'

The above exception was the direct cause of the following exception:

[0;31mImportError[0m                               Traceback (most recent call last)
[0;32m<ipython-input-1-870cef225c47>[0m in [0;36m<module>[0;34m[0m
[1;32m      2[0m [0;32mimport[0m [0mpandas[0m [0;32mas[0m [0mpd[0m[0;34m[0m[0;34m[0m[0m
[1;32m      3[0m [0;32mimport[0m [0mmatplotlib[0m[0;34m.[0m[0mpyplot[0m [0;32mas[0m [0mplt[0m[0;34m[0m[0;34m[0m[0m
[0;32m----> 4[0;31m [0;32mimport[0m [0mdask[0m[0;34m.[0m[0mbag[0m [0;32mas[0m [0mdb[0m[0;34m[0m[0;34m[0m[0m
[0m[1;32m      5[0m [0;32mfrom[0m [0mdask[0m[0;34m.[0m[0mdistributed[0m [0;32mimport[0m [0mClient[0m[0;34m[0m[0;34m[0m[0m
[1;32m      6[0m [0;32mimport[0m [0mjson[0m[0;34m[0m[0;34m[0m[0m

[0;32m/Library/Frameworks/Python.framework/Versions/3.8/lib/python3.8/site-packages/dask/bag/__init__.py[0m in [0;36m<module>[0;34m[0m
[1;32m     24[0m         [0;34m'  python -m pip install "dask[bag]" --upgrade  # or python -m pip install'[0m[0;34m[0m[0;34m[0m[0m
[1;32m     25[0m     )
[0;32m---> 26[0;31m     [0;32mraise[0m [0mImportError[0m[0;34m([0m[0mstr[0m[0;34m([0m[0me[0m[0;34m)[0m [0;34m+[0m [0;34m"\n\n"[0m [0;34m+[0m [0mmsg[0m[0;34m)[0m [0;32mfrom[0m [0me[0m[0;34m[0m[0;34m[0m[0m
[0m
[0;31mImportError[0m: No module named 'tlz'

Dask bag requirements are not installed.

Please either conda or pip install as follows:

  conda install dask               # either conda install
  python -m pip install "dask[bag]" --upgrade  # or python -m pip install
ImportError: No module named 'tlz'

Dask bag requirements are not installed.

Please either conda or pip install as follows:

  conda install dask               # either conda install
  python -m pip install "dask[bag]" --upgrade  # or python -m pip install

